Traceback (most recent call last):
  File "/usr/local/lib/python3.8/dist-packages/jupyter_cache/executors/utils.py", line 51, in single_nb_execution
    executenb(
  File "/usr/local/lib/python3.8/dist-packages/nbclient/client.py", line 1204, in execute
    return NotebookClient(nb=nb, resources=resources, km=km, **kwargs).execute()
  File "/usr/local/lib/python3.8/dist-packages/nbclient/util.py", line 84, in wrapped
    return just_run(coro(*args, **kwargs))
  File "/usr/local/lib/python3.8/dist-packages/nbclient/util.py", line 62, in just_run
    return loop.run_until_complete(coro)
  File "/usr/lib/python3.8/asyncio/base_events.py", line 616, in run_until_complete
    return future.result()
  File "/usr/local/lib/python3.8/dist-packages/nbclient/client.py", line 663, in async_execute
    await self.async_execute_cell(
  File "/usr/local/lib/python3.8/dist-packages/nbclient/client.py", line 965, in async_execute_cell
    await self._check_raise_for_error(cell, cell_index, exec_reply)
  File "/usr/local/lib/python3.8/dist-packages/nbclient/client.py", line 862, in _check_raise_for_error
    raise CellExecutionError.from_cell_and_msg(cell, exec_reply_content)
nbclient.exceptions.CellExecutionError: An error occurred while executing the following cell:
------------------
from sklearn.feature_selection import mutual_info_classif
mutual_info = mutual_info_classif(X_train, y_train)
mutual_info
------------------

[0;31m[0m
[0;31mImportError[0mTraceback (most recent call last)
[0;32m<ipython-input-28-0ab21a944ea7>[0m in [0;36m<module>[0;34m[0m
[0;32m----> 1[0;31m [0;32mfrom[0m [0msklearn[0m[0;34m.[0m[0mfeature_selection[0m [0;32mimport[0m [0mmutual_info_classif[0m[0;34m[0m[0;34m[0m[0m
[0m[1;32m      2[0m [0mmutual_info[0m [0;34m=[0m [0mmutual_info_classif[0m[0;34m([0m[0mX_train[0m[0;34m,[0m [0my_train[0m[0;34m)[0m[0;34m[0m[0;34m[0m[0m
[1;32m      3[0m [0mmutual_info[0m[0;34m[0m[0;34m[0m[0m

[0;32m/usr/local/lib/python3.8/dist-packages/sklearn/feature_selection/__init__.py[0m in [0;36m<module>[0;34m[0m
[1;32m      5[0m """
[1;32m      6[0m [0;34m[0m[0m
[0;32m----> 7[0;31m [0;32mfrom[0m [0;34m.[0m[0m_univariate_selection[0m [0;32mimport[0m [0mchi2[0m[0;34m[0m[0;34m[0m[0m
[0m[1;32m      8[0m [0;32mfrom[0m [0;34m.[0m[0m_univariate_selection[0m [0;32mimport[0m [0mf_classif[0m[0;34m[0m[0;34m[0m[0m
[1;32m      9[0m [0;32mfrom[0m [0;34m.[0m[0m_univariate_selection[0m [0;32mimport[0m [0mf_oneway[0m[0;34m[0m[0;34m[0m[0m

[0;32m/usr/local/lib/python3.8/dist-packages/sklearn/feature_selection/_univariate_selection.py[0m in [0;36m<module>[0;34m[0m
[1;32m     18[0m [0;32mfrom[0m [0;34m.[0m[0;34m.[0m[0mutils[0m[0;34m.[0m[0mextmath[0m [0;32mimport[0m [0msafe_sparse_dot[0m[0;34m,[0m [0mrow_norms[0m[0;34m[0m[0;34m[0m[0m
[1;32m     19[0m [0;32mfrom[0m [0;34m.[0m[0;34m.[0m[0mutils[0m[0;34m.[0m[0mvalidation[0m [0;32mimport[0m [0mcheck_is_fitted[0m[0;34m[0m[0;34m[0m[0m
[0;32m---> 20[0;31m [0;32mfrom[0m [0;34m.[0m[0;34m.[0m[0mutils[0m[0;34m.[0m[0m_param_validation[0m [0;32mimport[0m [0mInterval[0m[0;34m,[0m [0mStrOptions[0m[0;34m[0m[0;34m[0m[0m
[0m[1;32m     21[0m [0;32mfrom[0m [0;34m.[0m[0m_base[0m [0;32mimport[0m [0mSelectorMixin[0m[0;34m[0m[0;34m[0m[0m
[1;32m     22[0m [0;34m[0m[0m

[0;32m/usr/local/lib/python3.8/dist-packages/sklearn/utils/_param_validation.py[0m in [0;36m<module>[0;34m[0m
[1;32m     15[0m [0;32mfrom[0m [0mscipy[0m[0;34m.[0m[0msparse[0m [0;32mimport[0m [0mcsr_matrix[0m[0;34m[0m[0;34m[0m[0m
[1;32m     16[0m [0;34m[0m[0m
[0;32m---> 17[0;31m [0;32mfrom[0m [0;34m.[0m[0mvalidation[0m [0;32mimport[0m [0m_is_arraylike_not_scalar[0m[0;34m[0m[0;34m[0m[0m
[0m[1;32m     18[0m [0;34m[0m[0m
[1;32m     19[0m [0;34m[0m[0m

[0;31mImportError[0m: cannot import name '_is_arraylike_not_scalar' from 'sklearn.utils.validation' (/usr/local/lib/python3.8/dist-packages/sklearn/utils/validation.py)

[0;31m---------------------------------------------------------------------------[0;32m
NOTE: If your import is failing due to a missing package, you can
manually install dependencies using either !pip or !apt.

To view examples of installing some common dependencies, click the
"Open Examples" button below.
[0;31m---------------------------------------------------------------------------[0m

ImportError: cannot import name '_is_arraylike_not_scalar' from 'sklearn.utils.validation' (/usr/local/lib/python3.8/dist-packages/sklearn/utils/validation.py)

